2018-05-31 11:15:11,318 ERROR: Exception on /api/measures [POST] [in /Users/lucamaiano/miniconda3/lib/python3.6/site-packages/flask/app.py:1761]
Traceback (most recent call last):
  File "/Users/lucamaiano/miniconda3/lib/python3.6/site-packages/flask/app.py", line 2292, in wsgi_app
    response = self.full_dispatch_request()
  File "/Users/lucamaiano/miniconda3/lib/python3.6/site-packages/flask/app.py", line 1815, in full_dispatch_request
    rv = self.handle_user_exception(e)
  File "/Users/lucamaiano/miniconda3/lib/python3.6/site-packages/flask/app.py", line 1718, in handle_user_exception
    reraise(exc_type, exc_value, tb)
  File "/Users/lucamaiano/miniconda3/lib/python3.6/site-packages/flask/_compat.py", line 35, in reraise
    raise value
  File "/Users/lucamaiano/miniconda3/lib/python3.6/site-packages/flask/app.py", line 1813, in full_dispatch_request
    rv = self.dispatch_request()
  File "/Users/lucamaiano/miniconda3/lib/python3.6/site-packages/flask/app.py", line 1799, in dispatch_request
    return self.view_functions[rule.endpoint](**req.view_args)
  File "/Users/lucamaiano/Desktop/visualization/app/api/measures.py", line 30, in add_measurement
    response = jsonify(Measurements.to_dict(data))
AttributeError: type object 'Measurements' has no attribute 'to_dict'
2018-05-31 11:20:24,706 INFO: Lung System startup [in /Users/lucamaiano/Desktop/visualization/app/__init__.py:46]
2018-05-31 11:20:27,723 ERROR: Exception on /api/measures [POST] [in /Users/lucamaiano/miniconda3/lib/python3.6/site-packages/flask/app.py:1761]
Traceback (most recent call last):
  File "/Users/lucamaiano/miniconda3/lib/python3.6/site-packages/flask/app.py", line 2292, in wsgi_app
    response = self.full_dispatch_request()
  File "/Users/lucamaiano/miniconda3/lib/python3.6/site-packages/flask/app.py", line 1815, in full_dispatch_request
    rv = self.handle_user_exception(e)
  File "/Users/lucamaiano/miniconda3/lib/python3.6/site-packages/flask/app.py", line 1718, in handle_user_exception
    reraise(exc_type, exc_value, tb)
  File "/Users/lucamaiano/miniconda3/lib/python3.6/site-packages/flask/_compat.py", line 35, in reraise
    raise value
  File "/Users/lucamaiano/miniconda3/lib/python3.6/site-packages/flask/app.py", line 1813, in full_dispatch_request
    rv = self.dispatch_request()
  File "/Users/lucamaiano/miniconda3/lib/python3.6/site-packages/flask/app.py", line 1799, in dispatch_request
    return self.view_functions[rule.endpoint](**req.view_args)
  File "/Users/lucamaiano/Desktop/visualization/app/api/measures.py", line 30, in add_measurement
    response = jsonify(Measurements.to_dict(data))
  File "/Users/lucamaiano/Desktop/visualization/app/models.py", line 176, in to_dict
    day, hour, pressure, humidity, temperature, gas = None
TypeError: 'NoneType' object is not iterable
2018-05-31 11:21:45,879 INFO: Lung System startup [in /Users/lucamaiano/Desktop/visualization/app/__init__.py:46]
2018-05-31 11:21:47,817 ERROR: Exception on /api/measures [POST] [in /Users/lucamaiano/miniconda3/lib/python3.6/site-packages/flask/app.py:1761]
Traceback (most recent call last):
  File "/Users/lucamaiano/miniconda3/lib/python3.6/site-packages/flask/app.py", line 2292, in wsgi_app
    response = self.full_dispatch_request()
  File "/Users/lucamaiano/miniconda3/lib/python3.6/site-packages/flask/app.py", line 1815, in full_dispatch_request
    rv = self.handle_user_exception(e)
  File "/Users/lucamaiano/miniconda3/lib/python3.6/site-packages/flask/app.py", line 1718, in handle_user_exception
    reraise(exc_type, exc_value, tb)
  File "/Users/lucamaiano/miniconda3/lib/python3.6/site-packages/flask/_compat.py", line 35, in reraise
    raise value
  File "/Users/lucamaiano/miniconda3/lib/python3.6/site-packages/flask/app.py", line 1813, in full_dispatch_request
    rv = self.dispatch_request()
  File "/Users/lucamaiano/miniconda3/lib/python3.6/site-packages/flask/app.py", line 1799, in dispatch_request
    return self.view_functions[rule.endpoint](**req.view_args)
  File "/Users/lucamaiano/Desktop/visualization/app/api/measures.py", line 30, in add_measurement
    response = jsonify(Measurements.to_dict(data))
  File "/Users/lucamaiano/Desktop/visualization/app/models.py", line 176, in to_dict
    day, hour = ''
ValueError: not enough values to unpack (expected 2, got 0)
2018-05-31 11:23:19,257 INFO: Lung System startup [in /Users/lucamaiano/Desktop/visualization/app/__init__.py:46]
2018-05-31 11:23:35,948 INFO: Lung System startup [in /Users/lucamaiano/Desktop/visualization/app/__init__.py:46]
2018-05-31 11:23:37,389 ERROR: Exception on /api/measures [POST] [in /Users/lucamaiano/miniconda3/lib/python3.6/site-packages/flask/app.py:1761]
Traceback (most recent call last):
  File "/Users/lucamaiano/miniconda3/lib/python3.6/site-packages/flask/app.py", line 2292, in wsgi_app
    response = self.full_dispatch_request()
  File "/Users/lucamaiano/miniconda3/lib/python3.6/site-packages/flask/app.py", line 1815, in full_dispatch_request
    rv = self.handle_user_exception(e)
  File "/Users/lucamaiano/miniconda3/lib/python3.6/site-packages/flask/app.py", line 1718, in handle_user_exception
    reraise(exc_type, exc_value, tb)
  File "/Users/lucamaiano/miniconda3/lib/python3.6/site-packages/flask/_compat.py", line 35, in reraise
    raise value
  File "/Users/lucamaiano/miniconda3/lib/python3.6/site-packages/flask/app.py", line 1813, in full_dispatch_request
    rv = self.dispatch_request()
  File "/Users/lucamaiano/miniconda3/lib/python3.6/site-packages/flask/app.py", line 1799, in dispatch_request
    return self.view_functions[rule.endpoint](**req.view_args)
  File "/Users/lucamaiano/Desktop/visualization/app/api/measures.py", line 30, in add_measurement
    response = jsonify(Measurements.to_dict(data))
  File "/Users/lucamaiano/Desktop/visualization/app/models.py", line 198, in to_dict
    m = Measurements(day, hour, pressure, humidity, temperature, gas)
TypeError: __init__() takes 1 positional argument but 7 were given
2018-05-31 11:28:31,325 INFO: Lung System startup [in /Users/lucamaiano/Desktop/visualization/app/__init__.py:46]
2018-05-31 11:42:00,617 INFO: Lung System startup [in /Users/lucamaiano/Desktop/visualization/app/__init__.py:46]
2018-05-31 11:42:50,697 INFO: Lung System startup [in /Users/lucamaiano/Desktop/visualization/app/__init__.py:46]
2018-05-31 11:43:11,217 INFO: Lung System startup [in /Users/lucamaiano/Desktop/visualization/app/__init__.py:46]
2018-05-31 11:46:33,989 INFO: Lung System startup [in /Users/lucamaiano/Desktop/visualization/app/__init__.py:46]
2018-05-31 11:46:38,256 ERROR: Exception on /table [GET] [in /Users/lucamaiano/miniconda3/lib/python3.6/site-packages/flask/app.py:1761]
Traceback (most recent call last):
  File "/Users/lucamaiano/miniconda3/lib/python3.6/site-packages/flask/app.py", line 2292, in wsgi_app
    response = self.full_dispatch_request()
  File "/Users/lucamaiano/miniconda3/lib/python3.6/site-packages/flask/app.py", line 1815, in full_dispatch_request
    rv = self.handle_user_exception(e)
  File "/Users/lucamaiano/miniconda3/lib/python3.6/site-packages/flask/app.py", line 1718, in handle_user_exception
    reraise(exc_type, exc_value, tb)
  File "/Users/lucamaiano/miniconda3/lib/python3.6/site-packages/flask/_compat.py", line 35, in reraise
    raise value
  File "/Users/lucamaiano/miniconda3/lib/python3.6/site-packages/flask/app.py", line 1813, in full_dispatch_request
    rv = self.dispatch_request()
  File "/Users/lucamaiano/miniconda3/lib/python3.6/site-packages/flask/app.py", line 1799, in dispatch_request
    return self.view_functions[rule.endpoint](**req.view_args)
  File "/Users/lucamaiano/miniconda3/lib/python3.6/site-packages/flask_login/utils.py", line 261, in decorated_view
    return func(*args, **kwargs)
  File "/Users/lucamaiano/Desktop/visualization/app/main/routes.py", line 34, in table
    return render_template('table.html', title='Measurements', measures=measures)
  File "/Users/lucamaiano/miniconda3/lib/python3.6/site-packages/flask/templating.py", line 135, in render_template
    context, ctx.app)
  File "/Users/lucamaiano/miniconda3/lib/python3.6/site-packages/flask/templating.py", line 117, in _render
    rv = template.render(context)
  File "/Users/lucamaiano/miniconda3/lib/python3.6/site-packages/jinja2/asyncsupport.py", line 76, in render
    return original_render(self, *args, **kwargs)
  File "/Users/lucamaiano/miniconda3/lib/python3.6/site-packages/jinja2/environment.py", line 1008, in render
    return self.environment.handle_exception(exc_info, True)
  File "/Users/lucamaiano/miniconda3/lib/python3.6/site-packages/jinja2/environment.py", line 780, in handle_exception
    reraise(exc_type, exc_value, tb)
  File "/Users/lucamaiano/miniconda3/lib/python3.6/site-packages/jinja2/_compat.py", line 37, in reraise
    raise value.with_traceback(tb)
  File "/Users/lucamaiano/Desktop/visualization/app/templates/table.html", line 1, in top-level template code
    {% extends "base.html" %}
  File "/Users/lucamaiano/Desktop/visualization/app/templates/base.html", line 165, in top-level template code
    {% block content %}{% endblock %}
  File "/Users/lucamaiano/Desktop/visualization/app/templates/table.html", line 28, in block "content"
    {%- for par in measure %}
TypeError: 'Measurements' object is not iterable
2018-05-31 11:47:13,061 INFO: Lung System startup [in /Users/lucamaiano/Desktop/visualization/app/__init__.py:46]
